<?xml version="1.0"?>
<robot xmlns:xacro="http://www.ros.org/wiki/xacro" name="firefighter">

  <!-- A property for potential parameterization -->
  <xacro:property name="width" value=".2" />

  <!-- Link Definitions -->

  <link name="joint1">
    <visual>
      <geometry>
        <mesh filename="package://mycobot_description/urdf/mycobot_280_m5/joint1.stl"/>
      </geometry>
      <origin xyz="0.0 0 0" rpy="0 0 -1.5708"/>
    </visual>
    <collision>
      <geometry>
        <mesh filename="package://mycobot_description/urdf/mycobot_280_m5/joint1.stl"/>
      </geometry>
      <origin xyz="0.0 0 0" rpy="0 0 -1.5708"/>
    </collision>
  </link>

  <link name="joint2">
    <visual>
      <geometry>
        <mesh filename="package://mycobot_description/urdf/mycobot_280_m5/joint2.stl"/>
      </geometry>
      <origin xyz="0.0 0 -0.06096" rpy="0 0 -1.5708"/>
    </visual>
    <collision>
      <geometry>
        <mesh filename="package://mycobot_description/urdf/mycobot_280_m5/joint2.stl"/>
      </geometry>
      <origin xyz="0.0 0 -0.06096" rpy="0 0 -1.5708"/>
    </collision>
  </link>

  <link name="joint3">
    <visual>
      <geometry>
        <mesh filename="package://mycobot_description/urdf/mycobot_280_m5/joint3.stl"/>
      </geometry>
      <origin xyz="0.0 0 0.03256" rpy="0 -1.5708 0"/>
    </visual>
    <collision>
      <geometry>
        <mesh filename="package://mycobot_description/urdf/mycobot_280_m5/joint3.stl"/>
      </geometry>
      <origin xyz="0.0 0 0.03256" rpy="0 -1.5708 0"/>
    </collision>
  </link>

  <link name="joint4">
    <visual>
      <geometry>
        <mesh filename="package://mycobot_description/urdf/mycobot_280_m5/joint4.stl"/>
      </geometry>
      <origin xyz="0.0 0 0.03056" rpy="0 -1.5708 0"/>
    </visual>
    <collision>
      <geometry>
        <mesh filename="package://mycobot_description/urdf/mycobot_280_m5/joint4.stl"/>
      </geometry>
      <origin xyz="0.0 0 0.03056" rpy="0 -1.5708 0"/>
    </collision>
  </link>

  <link name="joint5">
    <visual>
      <geometry>
        <mesh filename="package://mycobot_description/urdf/mycobot_280_m5/joint5.stl"/>
      </geometry>
      <origin xyz="0.0 0 -0.03356" rpy="-1.5708 0 0"/>
    </visual>
    <collision>
      <geometry>
        <mesh filename="package://mycobot_description/urdf/mycobot_280_m5/joint5.stl"/>
      </geometry>
      <origin xyz="0.0 0 -0.03356" rpy="-1.5708 0 0"/>
    </collision>
  </link>

  <link name="joint6">
    <visual>
      <geometry>
        <mesh filename="package://mycobot_description/urdf/mycobot_280_m5/joint6.stl"/>
      </geometry>
      <origin xyz="0 0.00 -0.038" rpy="0 0 0"/>
    </visual>
    <collision>
      <geometry>
        <mesh filename="package://mycobot_description/urdf/mycobot_280_m5/joint6.stl"/>
      </geometry>
      <origin xyz="0 0.00 -0.038" rpy="0 0 0"/>
    </collision>
  </link>

  <link name="joint6_flange">
    <visual>
      <geometry>
        <mesh filename="package://mycobot_description/urdf/mycobot_280_m5/joint7.stl"/>
      </geometry>
      <origin xyz="0.0 0 -0.012" rpy="0 0 0"/>
    </visual>
    <collision>
      <geometry>
        <mesh filename="package://mycobot_description/urdf/mycobot_280_m5/joint7.stl"/>
      </geometry>
      <origin xyz="0.0 0 -0.012" rpy="0 0 0"/>
    </collision>
  </link>
  
  <!-- New Piece: specholder_tf link -->
  <link name="specholder_tf">
    <visual>
      <geometry>
        <mesh filename="package://mycobot_description/urdf/mycobot_280_m5/specholder_tf.stl"/>
      </geometry>
      <origin xyz="0 0 0" rpy="0 0 0"/>
    </visual>
    <collision>
      <geometry>
        <mesh filename="package://mycobot_description/urdf/mycobot_280_m5/specholder_tf.stl"/>
      </geometry>
      <origin xyz="0 0 0" rpy="0 0 0"/>
    </collision>
  </link>
  
  <!-- Joint Definitions for the original robot -->

  <joint name="joint2_to_joint1" type="revolute">
    <axis xyz="0 0 1"/>
    <limit effort="1000.0" lower="-3.14" upper="3.14159" velocity="0"/>
    <parent link="joint1"/>
    <child link="joint2"/>
    <origin xyz="0 0 0.13156" rpy="0 0 0"/>
  </joint>

  <joint name="joint3_to_joint2" type="revolute">
    <axis xyz="0 0 1"/>
    <limit effort="1000.0" lower="-3.14" upper="3.14159" velocity="0"/>
    <parent link="joint2"/>
    <child link="joint3"/>
    <origin xyz="0 0 0" rpy="0 1.5708 -1.5708"/>
  </joint>

  <joint name="joint4_to_joint3" type="revolute">
    <axis xyz="0 0 1"/>
    <limit effort="1000.0" lower="-3.14" upper="3.14159" velocity="0"/>
    <parent link="joint3"/>
    <child link="joint4"/>
    <origin xyz="-0.1104 0 0" rpy="0 0 0"/>
  </joint>

  <joint name="joint5_to_joint4" type="revolute">
    <axis xyz="0 0 1"/>
    <limit effort="1000.0" lower="-3.14" upper="3.14159" velocity="0"/>
    <parent link="joint4"/>
    <child link="joint5"/>
    <origin xyz="-0.096 0 0.06462" rpy="0 0 -1.5708"/>
  </joint>

  <joint name="joint6_to_joint5" type="revolute">
    <axis xyz="0 0 1"/>
    <limit effort="1000.0" lower="-3.14" upper="3.14159" velocity="0"/>
    <parent link="joint5"/>
    <child link="joint6"/>
    <origin xyz="0 -0.07318 0" rpy="1.5708 -1.5708 0"/>
  </joint>

  <joint name="joint6output_to_joint6" type="revolute">
    <axis xyz="0 0 1"/>
    <limit effort="1000.0" lower="-3.14" upper="3.14159" velocity="0"/>
    <parent link="joint6"/>
    <child link="joint6_flange"/>
    <origin xyz="0 0.0456 0" rpy="-1.5708 0 0"/>
  </joint>

  <!-- Fixed joint attaching the specholder_tf link to joint6_flange with a Z offset -->
  <joint name="specholder_tf_joint" type="fixed">
    <parent link="joint6_flange"/>
    <child link="specholder_tf"/>
    <!-- This origin shifts the specholder_tf 0.014 m upward (along the Z-axis) relative to joint6_flange -->
    <origin xyz="0 0 -0.014" rpy="0 0 0"/>
  </joint>

</robot>

